Workbook

Sheet Summary
A1: `
A2: 87 success criteria, classified by the checklist’s Validation Approach. LOE = net-new engineering beyond partner-provided automated checks. Effort in dev-days (blended senior eng); ≈ weeks = midpoint ÷ 5.
A3: KEY FINDING: with the partner covering automated Level A/AA, the net-new gap is almost entirely AGENTIC (AI) + HUMAN-IN-THE-LOOP — not more automated checks. Adjust the “Coverage Source” column against the partner’s real SC list.
A5: A · Net-new build by phase (Required A/AA = Phases 1–2)
A6: Phase | B6: Criteria | C6: LOE low (d) | D6: LOE high (d) | E6: ≈ weeks
A7: Phase 1 · Agentic (Req. A/AA) | B7: =COUNTIF('Coverage Matrix'!J:J,A7) | C7: =SUMIF('Coverage Matrix'!J:J,A7,'Coverage Matrix'!K:K) | D7: =SUMIF('Coverage Matrix'!J:J,A7,'Coverage Matrix'!L:L) | E7: =ROUND(AVERAGE(C7:D7)/5,1)
A8: Phase 2 · HITL (Req. A/AA) | B8: =COUNTIF('Coverage Matrix'!J:J,A8) | C8: =SUMIF('Coverage Matrix'!J:J,A8,'Coverage Matrix'!K:K) | D8: =SUMIF('Coverage Matrix'!J:J,A8,'Coverage Matrix'!L:L) | E8: =ROUND(AVERAGE(C8:D8)/5,1)
A9: Phase 3 · Optional / AAA | B9: =COUNTIF('Coverage Matrix'!J:J,A9) | C9: =SUMIF('Coverage Matrix'!J:J,A9,'Coverage Matrix'!K:K) | D9: =SUMIF('Coverage Matrix'!J:J,A9,'Coverage Matrix'!L:L) | E9: =ROUND(AVERAGE(C9:D9)/5,1)
A11: B · One-time + conditional workstreams
A12: Work item | B12: Criteria | C12: LOE low (d) | D12: LOE high (d) | E12: ≈ weeks
A13: Phase 0 · coverage audit + check contract + golden corpus | B13: — | C13: 5 | D13: 8 | E13: =ROUND(AVERAGE(C13:D13)/5,1)
A14: HITL platform hardening (queue, evidence, sign-off) | B14: — | C14: 15 | D14: 25 | E14: =ROUND(AVERAGE(C14:D14)/5,1)
A15: Conditional · document-format automated parity (if partner is web-only) | B15: =COUNTIF('Coverage Matrix'!H:H,"Partner baseline") | C15: =B15*1 | D15: =B15*2.5 | E15: =ROUND(AVERAGE(C15:D15)/5,1)
A17: TOTAL → Required A/AA conformance (Phases 1–2 + Phase 0 + platform) | C17: =SUMIF('Coverage Matrix'!J:J,"Phase 1*",'Coverage Matrix'!K:K)+SUMIF('Coverage Matrix'!J:J,"Phase 2*",'Coverage Matrix'!K:K)+SUM(C13:C14) | D17: =SUMIF('Coverage Matrix'!J:J,"Phase 1*",'Coverage Matrix'!L:L)+SUMIF('Coverage Matrix'!J:J,"Phase 2*",'Coverage Matrix'!L:L)+SUM(D13:D14) | E17: =ROUND(AVERAGE(C17:D17)/5,1)
A18: TOTAL → incl. AAA / Optional (Phase 3) | C18: =C17+SUMIF('Coverage Matrix'!J:J,"Phase 3*",'Coverage Matrix'!K:K) | D18: =D17+SUMIF('Coverage Matrix'!J:J,"Phase 3*",'Coverage Matrix'!L:L) | E18: =ROUND(AVERAGE(C18:D18)/5,1)
A20: C · Coverage today
A21: Coverage source | B21: Criteria
A22: Shipped (demo) | B22: =COUNTIF('Coverage Matrix'!H:H,A22)
A23: Partner baseline | B23: =COUNTIF('Coverage Matrix'!H:H,A23)
A24: MDK net-new | B24: =COUNTIF('Coverage Matrix'!H:H,A24)
A25: All success criteria | B25: =COUNTA('Coverage Matrix'!A2:A88)

Sheet Coverage Matrix
A1: SC | B1: Success Criterion | C1: Level | D1: Added In | E1: Legal | F1: Principle | G1: Validation Approach | H1: Coverage Source | I1: Build Tier | J1: Phase | K1: LOE low (d) | L1: LOE high (d) | M1: Requirement | N1: How to Test | O1: Notes
A2: 1.1.1 | B2: Non-text Content | C2: A | D2: 2.0 | E2: Required | F2: Perceivable | G2: Automated + Agentic | H2: Shipped (demo) | I2: Tier 2 · Agentic AI | J2: — | M2: All non-text content (images, icons, charts, controls) has a text alternative serving the equivalent purpose; decorative images are marked as such. | N2: Check alt text; verify with a screen reader (NVDA/VoiceOver); confirm decorative images use null alt / aria-hidden.
A3: 1.2.1 | B3: Audio-only & Video-only (Prerecorded) | C3: A | D3: 2.0 | E3: Required | F3: Perceivable | G3: Human / AT | H3: MDK net-new | I3: Tier 3 · HITL workflow | J3: Phase 2 · HITL (Req. A/AA) | K3: 1 | L3: 2 | M3: Provide a transcript for prerecorded audio-only and a transcript or audio track for prerecorded video-only. | N3: Manual media review; confirm transcript/description is present.
A4: 1.2.2 | B4: Captions (Prerecorded) | C4: A | D4: 2.0 | E4: Required | F4: Perceivable | G4: Human / AT | H4: MDK net-new | I4: Tier 3 · HITL workflow | J4: Phase 2 · HITL (Req. A/AA) | K4: 1 | L4: 2 | M4: Synchronized captions for all prerecorded audio in video. | N4: Play media; verify accurate, synchronized captions.
A5: 1.2.3 | B5: Audio Description or Media Alternative (Prerecorded) | C5: A | D5: 2.0 | E5: Required | F5: Perceivable | G5: Human / AT | H5: MDK net-new | I5: Tier 3 · HITL workflow | J5: Phase 2 · HITL (Req. A/AA) | K5: 1 | L5: 2 | M5: Audio description or full text alternative for prerecorded video. | N5: Manual review for an audio-description track or transcript.
A6: 1.2.4 | B6: Captions (Live) | C6: AA | D6: 2.0 | E6: Required | F6: Perceivable | G6: Human / AT | H6: MDK net-new | I6: Tier 3 · HITL workflow | J6: Phase 2 · HITL (Req. A/AA) | K6: 1 | L6: 2 | M6: Real-time captions for live audio content. | N6: Verify live captioning on streamed/live media.
A7: 1.2.5 | B7: Audio Description (Prerecorded) | C7: AA | D7: 2.0 | E7: Required | F7: Perceivable | G7: Human / AT | H7: MDK net-new | I7: Tier 3 · HITL workflow | J7: Phase 2 · HITL (Req. A/AA) | K7: 1 | L7: 2 | M7: Audio description provided for all prerecorded video. | N7: Confirm a described audio track exists.
A8: 1.2.6 | B8: Sign Language (Prerecorded) | C8: AAA | D8: 2.0 | E8: Optional | F8: Perceivable | G8: Human / AT | H8: MDK net-new | I8: Tier 3 · HITL workflow | J8: Phase 3 · Optional / AAA | K8: 1 | L8: 2 | M8: Sign-language interpretation for prerecorded audio. | N8: Manual review.
A9: 1.2.7 | B9: Extended Audio Description (Prerecorded) | C9: AAA | D9: 2.0 | E9: Optional | F9: Perceivable | G9: Human / AT | H9: MDK net-new | I9: Tier 3 · HITL workflow | J9: Phase 3 · Optional / AAA | K9: 1 | L9: 2 | M9: Extended audio description where pauses in dialogue are insufficient. | N9: Manual review.
A10: 1.2.8 | B10: Media Alternative (Prerecorded) | C10: AAA | D10: 2.0 | E10: Optional | F10: Perceivable | G10: Human / AT | H10: MDK net-new | I10: Tier 3 · HITL workflow | J10: Phase 3 · Optional / AAA | K10: 1 | L10: 2 | M10: Full text alternative for prerecorded synchronized media. | N10: Confirm a complete transcript.
A11: 1.2.9 | B11: Audio-only (Live) | C11: AAA | D11: 2.0 | E11: Optional | F11: Perceivable | G11: Human / AT | H11: MDK net-new | I11: Tier 3 · HITL workflow | J11: Phase 3 · Optional / AAA | K11: 1 | L11: 2 | M11: Text alternative for live audio-only content. | N11: Manual review.
A12: 1.3.1 | B12: Info and Relationships | C12: A | D12: 2.0 | E12: Required | F12: Perceivable | G12: Automated + Agentic | H12: Shipped (demo) | I12: Tier 2 · Agentic AI | J12: — | M12: Structure/relationships shown visually are available programmatically (headings, lists, tables, form labels). | N12: Inspect semantic markup/ARIA; screen-reader test; automated scan (axe).
A13: 1.3.2 | B13: Meaningful Sequence | C13: A | D13: 2.0 | E13: Required | F13: Perceivable | G13: Human / AT | H13: Shipped (demo) | I13: Tier 3 · HITL workflow | J13: — | M13: DOM reading/navigation order is logical and correct. | N13: Disable CSS or use a screen reader to verify order.
A14: 1.3.3 | B14: Sensory Characteristics | C14: A | D14: 2.0 | E14: Required | F14: Perceivable | G14: Automated + Agentic | H14: MDK net-new | I14: Tier 2 · Agentic AI | J14: Phase 1 · Agentic (Req. A/AA) | K14: 4 | L14: 8 | M14: Instructions don't rely solely on shape, size, location, or sound (e.g. 'click the round button'). | N14: Manual review of instructional text.
A15: 1.3.4 | B15: Orientation | C15: AA | D15: 2.1 | E15: Required | F15: Perceivable | G15: Automated | H15: Partner baseline | I15: Tier 1 · Deterministic | J15: — | M15: Content not locked to one orientation (portrait/landscape) unless essential. | N15: Rotate device/viewport; confirm content adapts. | O15: Partner provides for web; net-new only for PDF/Office formats
A16: 1.3.5 | B16: Identify Input Purpose | C16: AA | D16: 2.1 | E16: Required | F16: Perceivable | G16: Automated | H16: Partner baseline | I16: Tier 1 · Deterministic | J16: — | M16: Inputs collecting user info use appropriate autocomplete tokens. | N16: Inspect autocomplete attributes on form fields. | O16: Partner provides for web; net-new only for PDF/Office formats
A17: 1.3.6 | B17: Identify Purpose | C17: AAA | D17: 2.1 | E17: Optional | F17: Perceivable | G17: Automated | H17: MDK net-new | I17: Tier 1 · Deterministic | J17: Phase 3 · Optional / AAA | K17: 1 | L17: 3 | M17: Purpose of UI components, icons, and regions is programmatically determinable. | N17: Inspect ARIA/landmark markup.
A18: 1.4.1 | B18: Use of Color | C18: A | D18: 2.0 | E18: Required | F18: Perceivable | G18: Human / AT | H18: MDK net-new | I18: Tier 3 · HITL workflow | J18: Phase 2 · HITL (Req. A/AA) | K18: 1 | L18: 2 | M18: Color is not the only means of conveying information (errors, links, states). | N18: Manual review; grayscale check.
A19: 1.4.2 | B19: Audio Control | C19: A | D19: 2.0 | E19: Required | F19: Perceivable | G19: Automated | H19: Partner baseline | I19: Tier 1 · Deterministic | J19: — | M19: Auto-playing audio over 3s can be paused/stopped or volume controlled. | N19: Verify a pause/stop control on autoplay audio. | O19: Partner provides for web; net-new only for PDF/Office formats
A20: 1.4.3 | B20: Contrast (Minimum) | C20: AA | D20: 2.0 | E20: Required | F20: Perceivable | G20: Automated | H20: Shipped (demo) | I20: Tier 1 · Deterministic | J20: — | M20: Text contrast >= 4.5:1 (>= 3:1 for large text: 18pt, or 14pt bold). | N20: Use a contrast analyzer on text/background pairs.
A21: 1.4.4 | B21: Resize Text | C21: AA | D21: 2.0 | E21: Required | F21: Perceivable | G21: Automated | H21: Partner baseline | I21: Tier 1 · Deterministic | J21: — | M21: Text resizable to 200% without loss of content or function. | N21: Zoom browser to 200%; check for clipping/overlap. | O21: Partner provides for web; net-new only for PDF/Office formats
A22: 1.4.5 | B22: Images of Text | C22: AA | D22: 2.0 | E22: Required | F22: Perceivable | G22: Automated | H22: Partner baseline | I22: Tier 1 · Deterministic | J22: — | M22: Use real text rather than images of text (except logos/essential cases). | N22: Identify text rendered as images. | O22: Partner provides for web; net-new only for PDF/Office formats
A23: 1.4.6 | B23: Contrast (Enhanced) | C23: AAA | D23: 2.0 | E23: Optional | F23: Perceivable | G23: Automated | H23: MDK net-new | I23: Tier 1 · Deterministic | J23: Phase 3 · Optional / AAA | K23: 1 | L23: 3 | M23: Text contrast >= 7:1 (>= 4.5:1 for large text). | N23: Contrast analyzer.
A24: 1.4.7 | B24: Low or No Background Audio | C24: AAA | D24: 2.0 | E24: Optional | F24: Perceivable | G24: Human / AT | H24: MDK net-new | I24: Tier 3 · HITL workflow | J24: Phase 3 · Optional / AAA | K24: 1 | L24: 2 | M24: Background audio behind speech is low/absent or can be turned off. | N24: Manual review.
A25: 1.4.8 | B25: Visual Presentation | C25: AAA | D25: 2.0 | E25: Optional | F25: Perceivable | G25: Human / AT | H25: MDK net-new | I25: Tier 3 · HITL workflow | J25: Phase 3 · Optional / AAA | K25: 1 | L25: 2 | M25: User control over text blocks: colors, width <= 80 chars, spacing, no justification. | N25: Manual review / user-setting test.
A26: 1.4.9 | B26: Images of Text (No Exception) | C26: AAA | D26: 2.0 | E26: Optional | F26: Perceivable | G26: Automated | H26: MDK net-new | I26: Tier 1 · Deterministic | J26: Phase 3 · Optional / AAA | K26: 1 | L26: 3 | M26: No images of text except where essential (e.g. logos). | N26: Manual review.
A27: 1.4.10 | B27: Reflow | C27: AA | D27: 2.1 | E27: Required | F27: Perceivable | G27: Automated | H27: Partner baseline | I27: Tier 1 · Deterministic | J27: — | M27: Content reflows to 320 CSS px wide without 2-D scrolling (1280px at 400% zoom). | N27: Zoom to 400% / 320px viewport; check for horizontal scroll. | O27: Partner provides for web; net-new only for PDF/Office formats
A28: 1.4.11 | B28: Non-text Contrast | C28: AA | D28: 2.1 | E28: Required | F28: Perceivable | G28: Automated | H28: Partner baseline | I28: Tier 1 · Deterministic | J28: — | M28: UI components and graphics have >= 3:1 contrast against adjacent colors. | N28: Contrast analyzer on buttons, borders, icons, focus rings. | O28: Partner provides for web; net-new only for PDF/Office formats
A29: 1.4.12 | B29: Text Spacing | C29: AA | D29: 2.1 | E29: Required | F29: Perceivable | G29: Automated | H29: Partner baseline | I29: Tier 1 · Deterministic | J29: — | M29: No loss of content when user overrides line/letter/word/paragraph spacing. | N29: Apply text-spacing bookmarklet; check for clipping. | O29: Partner provides for web; net-new only for PDF/Office formats
A30: 1.4.13 | B30: Content on Hover or Focus | C30: AA | D30: 2.1 | E30: Required | F30: Perceivable | G30: Human / AT | H30: MDK net-new | I30: Tier 3 · HITL workflow | J30: Phase 2 · HITL (Req. A/AA) | K30: 1 | L30: 2 | M30: Hover/focus content (tooltips, popovers) is dismissible, hoverable, and persistent. | N30: Test tooltips/menus with both keyboard and pointer.
A31: 2.1.1 | B31: Keyboard | C31: A | D31: 2.0 | E31: Required | F31: Operable | G31: Human / AT | H31: Shipped (demo) | I31: Tier 3 · HITL workflow | J31: — | M31: All functionality is operable via keyboard. | N31: Tab/arrow through all controls with no mouse.
A32: 2.1.2 | B32: No Keyboard Trap | C32: A | D32: 2.0 | E32: Required | F32: Operable | G32: Human / AT | H32: MDK net-new | I32: Tier 3 · HITL workflow | J32: Phase 2 · HITL (Req. A/AA) | K32: 1 | L32: 2 | M32: Keyboard focus can always move away from a component. | N32: Tab into and out of every widget/modal.
A33: 2.1.3 | B33: Keyboard (No Exception) | C33: AAA | D33: 2.0 | E33: Optional | F33: Operable | G33: Human / AT | H33: MDK net-new | I33: Tier 3 · HITL workflow | J33: Phase 3 · Optional / AAA | K33: 1 | L33: 2 | M33: All functionality keyboard-operable with no timing exceptions. | N33: Keyboard-only test.
A34: 2.1.4 | B34: Character Key Shortcuts | C34: A | D34: 2.1 | E34: Required | F34: Operable | G34: Human / AT | H34: MDK net-new | I34: Tier 3 · HITL workflow | J34: Phase 2 · HITL (Req. A/AA) | K34: 1 | L34: 2 | M34: Single-character shortcuts can be turned off, remapped, or active only on focus. | N34: Test single-key shortcuts; check settings.
A35: 2.2.1 | B35: Timing Adjustable | C35: A | D35: 2.0 | E35: Required | F35: Operable | G35: Human / AT | H35: MDK net-new | I35: Tier 3 · HITL workflow | J35: Phase 2 · HITL (Req. A/AA) | K35: 1 | L35: 2 | M35: Time limits can be turned off, adjusted, or extended. | N35: Identify timeouts; verify controls.
A36: 2.2.2 | B36: Pause, Stop, Hide | C36: A | D36: 2.0 | E36: Required | F36: Operable | G36: Human / AT | H36: MDK net-new | I36: Tier 3 · HITL workflow | J36: Phase 2 · HITL (Req. A/AA) | K36: 1 | L36: 2 | M36: Moving/blinking/auto-updating content can be paused, stopped, or hidden. | N36: Test carousels, animations, auto-refresh.
A37: 2.2.3 | B37: No Timing | C37: AAA | D37: 2.0 | E37: Optional | F37: Operable | G37: Human / AT | H37: MDK net-new | I37: Tier 3 · HITL workflow | J37: Phase 3 · Optional / AAA | K37: 1 | L37: 2 | M37: No time limits except for real-time events. | N37: Manual review.
A38: 2.2.4 | B38: Interruptions | C38: AAA | D38: 2.0 | E38: Optional | F38: Operable | G38: Human / AT | H38: MDK net-new | I38: Tier 3 · HITL workflow | J38: Phase 3 · Optional / AAA | K38: 1 | L38: 2 | M38: Interruptions can be postponed or suppressed by the user. | N38: Manual review.
A39: 2.2.5 | B39: Re-authenticating | C39: AAA | D39: 2.0 | E39: Optional | F39: Operable | G39: Human / AT | H39: MDK net-new | I39: Tier 3 · HITL workflow | J39: Phase 3 · Optional / AAA | K39: 1 | L39: 2 | M39: After session expiry, data is preserved on re-authentication. | N39: Test session timeout then resume.
A40: 2.2.6 | B40: Timeouts | C40: AAA | D40: 2.1 | E40: Optional | F40: Operable | G40: Human / AT | H40: MDK net-new | I40: Tier 3 · HITL workflow | J40: Phase 3 · Optional / AAA | K40: 1 | L40: 2 | M40: Users are warned of potential data loss from inactivity timeout. | N40: Check for timeout warnings.
...

Sheet By Tier
A1: Build tier | B1: Net-new | C1: LOE low (d) | D1: LOE high (d) | E1: Meaning
A2: Tier 1 · Deterministic | B2: =COUNTIFS('Coverage Matrix'!I:I,A2,'Coverage Matrix'!H:H,"MDK net-new") | C2: =SUMIFS('Coverage Matrix'!K:K,'Coverage Matrix'!I:I,A2,'Coverage Matrix'!H:H,"MDK net-new") | D2: =SUMIFS('Coverage Matrix'!L:L,'Coverage Matrix'!I:I,A2,'Coverage Matrix'!H:H,"MDK net-new") | E2: Rule on parsed document model; ×4 formats
A3: Tier 2 · Agentic AI | B3: =COUNTIFS('Coverage Matrix'!I:I,A3,'Coverage Matrix'!H:H,"MDK net-new") | C3: =SUMIFS('Coverage Matrix'!K:K,'Coverage Matrix'!I:I,A3,'Coverage Matrix'!H:H,"MDK net-new") | D3: =SUMIFS('Coverage Matrix'!L:L,'Coverage Matrix'!I:I,A3,'Coverage Matrix'!H:H,"MDK net-new") | E3: LLM evaluator + golden evals + confidence + HITL escalation
A4: Tier 3 · HITL workflow | B4: =COUNTIFS('Coverage Matrix'!I:I,A4,'Coverage Matrix'!H:H,"MDK net-new") | C4: =SUMIFS('Coverage Matrix'!K:K,'Coverage Matrix'!I:I,A4,'Coverage Matrix'!H:H,"MDK net-new") | D4: =SUMIFS('Coverage Matrix'!L:L,'Coverage Matrix'!I:I,A4,'Coverage Matrix'!H:H,"MDK net-new") | E4: Detector + routed human review + evidence capture
